{
 "cells": [
  {
   "cell_type": "code",
   "execution_count": 4,
   "metadata": {
    "colab": {
     "base_uri": "https://localhost:8080/"
    },
    "id": "vAM8-uPZPCuF",
    "outputId": "198893b1-4ace-4852-d7a8-0f97c785b09a"
   },
   "outputs": [],
   "source": [
    "from mtcnn import MTCNN\n",
    "import cv2"
   ]
  },
  {
   "cell_type": "code",
   "execution_count": 5,
   "metadata": {
    "colab": {
     "base_uri": "https://localhost:8080/"
    },
    "id": "2K04u1FIPLq2",
    "outputId": "fdb89227-5ba9-4628-a2ca-40496bdb61b6"
   },
   "outputs": [
    {
     "name": "stderr",
     "output_type": "stream",
     "text": [
      "2022-10-07 14:44:44.187228: W tensorflow/core/common_runtime/bfc_allocator.cc:290] Allocator (GPU_0_bfc) ran out of memory trying to allocate 40.92MiB with freed_by_count=0. The caller indicates that this is not a failure, but this may mean that there could be performance gains if more memory were available.\n",
      "2022-10-07 14:44:44.195692: W tensorflow/core/common_runtime/bfc_allocator.cc:290] Allocator (GPU_0_bfc) ran out of memory trying to allocate 83.28MiB with freed_by_count=0. The caller indicates that this is not a failure, but this may mean that there could be performance gains if more memory were available.\n",
      "2022-10-07 14:44:44.195766: W tensorflow/core/common_runtime/bfc_allocator.cc:290] Allocator (GPU_0_bfc) ran out of memory trying to allocate 83.28MiB with freed_by_count=0. The caller indicates that this is not a failure, but this may mean that there could be performance gains if more memory were available.\n",
      "2022-10-07 14:44:44.203679: W tensorflow/core/common_runtime/bfc_allocator.cc:290] Allocator (GPU_0_bfc) ran out of memory trying to allocate 1.16GiB with freed_by_count=0. The caller indicates that this is not a failure, but this may mean that there could be performance gains if more memory were available.\n",
      "2022-10-07 14:44:44.203755: W tensorflow/core/common_runtime/bfc_allocator.cc:290] Allocator (GPU_0_bfc) ran out of memory trying to allocate 1.16GiB with freed_by_count=0. The caller indicates that this is not a failure, but this may mean that there could be performance gains if more memory were available.\n",
      "2022-10-07 14:44:44.205668: E tensorflow/stream_executor/cuda/cuda_blas.cc:218] failed to create cublas handle: cublas error\n",
      "2022-10-07 14:44:44.205693: E tensorflow/stream_executor/cuda/cuda_blas.cc:220] Failure to initialize cublas may be due to OOM (cublas needs some free memory when you initialize it, and your deep-learning framework may have preallocated more than its fair share), or may be because this binary was not built with support for the GPU in your machine.\n",
      "2022-10-07 14:44:44.205860: W tensorflow/core/framework/op_kernel.cc:1780] OP_REQUIRES failed at conv_ops.cc:1134 : NOT_FOUND: No algorithm worked!  Error messages:\n",
      "  Profiling failure on CUDNN engine 1#TC: UNKNOWN: CUDNN_STATUS_EXECUTION_FAILED\n",
      "in tensorflow/stream_executor/cuda/cuda_dnn.cc(4023): 'cudnnConvolutionForward( cudnn.handle(), alpha, input_nd_.handle(), input_data.opaque(), filter_.handle(), filter_data.opaque(), conv_.handle(), ToConvForwardAlgo(algo), scratch_memory.opaque(), scratch_memory.size(), beta, output_nd_.handle(), output_data.opaque())'\n",
      "  Profiling failure on CUDNN engine 1: UNKNOWN: CUDNN_STATUS_EXECUTION_FAILED\n",
      "in tensorflow/stream_executor/cuda/cuda_dnn.cc(4023): 'cudnnConvolutionForward( cudnn.handle(), alpha, input_nd_.handle(), input_data.opaque(), filter_.handle(), filter_data.opaque(), conv_.handle(), ToConvForwardAlgo(algo), scratch_memory.opaque(), scratch_memory.size(), beta, output_nd_.handle(), output_data.opaque())'\n",
      "  Profiling failure on CUDNN engine 0#TC: UNKNOWN: CUDNN_STATUS_EXECUTION_FAILED\n",
      "in tensorflow/stream_executor/cuda/cuda_dnn.cc(4023): 'cudnnConvolutionForward( cudnn.handle(), alpha, input_nd_.handle(), input_data.opaque(), filter_.handle(), filter_data.opaque(), conv_.handle(), ToConvForwardAlgo(algo), scratch_memory.opaque(), scratch_memory.size(), beta, output_nd_.handle(), output_data.opaque())'\n",
      "  Profiling failure on CUDNN engine 0: UNKNOWN: CUDNN_STATUS_EXECUTION_FAILED\n",
      "in tensorflow/stream_executor/cuda/cuda_dnn.cc(4023): 'cudnnConvolutionForward( cudnn.handle(), alpha, input_nd_.handle(), input_data.opaque(), filter_.handle(), filter_data.opaque(), conv_.handle(), ToConvForwardAlgo(algo), scratch_memory.opaque(), scratch_memory.size(), beta, output_nd_.handle(), output_data.opaque())'\n",
      "  Profiling failure on CUDNN engine 2#TC: RESOURCE_EXHAUSTED: Out of memory while trying to allocate 87330160 bytes.\n",
      "  Profiling failure on CUDNN engine 2: RESOURCE_EXHAUSTED: Out of memory while trying to allocate 87330160 bytes.\n",
      "  Profiling failure on CUDNN engine 6#TC: UNKNOWN: CUDNN_STATUS_EXECUTION_FAILED\n",
      "in tensorflow/stream_executor/cuda/cuda_dnn.cc(4023): 'cudnnConvolutionForward( cudnn.handle(), alpha, input_nd_.handle(), input_data.opaque(), filter_.handle(), filter_data.opaque(), conv_.handle(), ToConvForwardAlgo(algo), scratch_memory.opaque(), scratch_memory.size(), beta, output_nd_.handle(), output_data.opaque())'\n",
      "  Profiling failure on CUDNN engine 6: UNKNOWN: CUDNN_STATUS_EXECUTION_FAILED\n",
      "in tensorflow/stream_executor/cuda/cuda_dnn.cc(4023): 'cudnnConvolutionForward( cudnn.handle(), alpha, input_nd_.handle(), input_data.opaque(), filter_.handle(), filter_data.opaque(), conv_.handle(), ToConvForwardAlgo(algo), scratch_memory.opaque(), scratch_memory.size(), beta, output_nd_.handle(), output_data.opaque())'\n",
      "  Profiling failure on CUDNN engine 5#TC: UNKNOWN: CUDNN_STATUS_INTERNAL_ERROR\n",
      "in tensorflow/stream_executor/cuda/cuda_dnn.cc(4023): 'cudnnConvolutionForward( cudnn.handle(), alpha, input_nd_.handle(), input_data.opaque(), filter_.handle(), filter_data.opaque(), conv_.handle(), ToConvForwardAlgo(algo), scratch_memory.opaque(), scratch_memory.size(), beta, output_nd_.handle(), output_data.opaque())'\n",
      "  Profiling failure on CUDNN engine 5: UNKNOWN: CUDNN_STATUS_INTERNAL_ERROR\n",
      "in tensorflow/stream_executor/cuda/cuda_dnn.cc(4023): 'cudnnConvolutionForward( cudnn.handle(), alpha, input_nd_.handle(), input_data.opaque(), filter_.handle(), filter_data.opaque(), conv_.handle(), ToConvForwardAlgo(algo), scratch_memory.opaque(), scratch_memory.size(), beta, output_nd_.handle(), output_data.opaque())'\n",
      "  Profiling failure on CUDNN engine 7#TC: RESOURCE_EXHAUSTED: Out of memory while trying to allocate 1246011616 bytes.\n",
      "  Profiling failure on CUDNN engine 7: RESOURCE_EXHAUSTED: Out of memory while trying to allocate 1246011616 bytes.\n"
     ]
    },
    {
     "ename": "NotFoundError",
     "evalue": "Graph execution error:\n\nDetected at node 'model_3/conv2d_12/Conv2D' defined at (most recent call last):\n    File \"/home/pushpesh/miniconda3/envs/tf/lib/python3.9/runpy.py\", line 197, in _run_module_as_main\n      return _run_code(code, main_globals, None,\n    File \"/home/pushpesh/miniconda3/envs/tf/lib/python3.9/runpy.py\", line 87, in _run_code\n      exec(code, run_globals)\n    File \"/home/pushpesh/miniconda3/envs/tf/lib/python3.9/site-packages/ipykernel_launcher.py\", line 17, in <module>\n      app.launch_new_instance()\n    File \"/home/pushpesh/miniconda3/envs/tf/lib/python3.9/site-packages/traitlets/config/application.py\", line 978, in launch_instance\n      app.start()\n    File \"/home/pushpesh/miniconda3/envs/tf/lib/python3.9/site-packages/ipykernel/kernelapp.py\", line 712, in start\n      self.io_loop.start()\n    File \"/home/pushpesh/miniconda3/envs/tf/lib/python3.9/site-packages/tornado/platform/asyncio.py\", line 199, in start\n      self.asyncio_loop.run_forever()\n    File \"/home/pushpesh/miniconda3/envs/tf/lib/python3.9/asyncio/base_events.py\", line 601, in run_forever\n      self._run_once()\n    File \"/home/pushpesh/miniconda3/envs/tf/lib/python3.9/asyncio/base_events.py\", line 1905, in _run_once\n      handle._run()\n    File \"/home/pushpesh/miniconda3/envs/tf/lib/python3.9/asyncio/events.py\", line 80, in _run\n      self._context.run(self._callback, *self._args)\n    File \"/home/pushpesh/miniconda3/envs/tf/lib/python3.9/site-packages/ipykernel/kernelbase.py\", line 510, in dispatch_queue\n      await self.process_one()\n    File \"/home/pushpesh/miniconda3/envs/tf/lib/python3.9/site-packages/ipykernel/kernelbase.py\", line 499, in process_one\n      await dispatch(*args)\n    File \"/home/pushpesh/miniconda3/envs/tf/lib/python3.9/site-packages/ipykernel/kernelbase.py\", line 406, in dispatch_shell\n      await result\n    File \"/home/pushpesh/miniconda3/envs/tf/lib/python3.9/site-packages/ipykernel/kernelbase.py\", line 730, in execute_request\n      reply_content = await reply_content\n    File \"/home/pushpesh/miniconda3/envs/tf/lib/python3.9/site-packages/ipykernel/ipkernel.py\", line 383, in do_execute\n      res = shell.run_cell(\n    File \"/home/pushpesh/miniconda3/envs/tf/lib/python3.9/site-packages/ipykernel/zmqshell.py\", line 528, in run_cell\n      return super().run_cell(*args, **kwargs)\n    File \"/home/pushpesh/miniconda3/envs/tf/lib/python3.9/site-packages/IPython/core/interactiveshell.py\", line 2885, in run_cell\n      result = self._run_cell(\n    File \"/home/pushpesh/miniconda3/envs/tf/lib/python3.9/site-packages/IPython/core/interactiveshell.py\", line 2940, in _run_cell\n      return runner(coro)\n    File \"/home/pushpesh/miniconda3/envs/tf/lib/python3.9/site-packages/IPython/core/async_helpers.py\", line 129, in _pseudo_sync_runner\n      coro.send(None)\n    File \"/home/pushpesh/miniconda3/envs/tf/lib/python3.9/site-packages/IPython/core/interactiveshell.py\", line 3139, in run_cell_async\n      has_raised = await self.run_ast_nodes(code_ast.body, cell_name,\n    File \"/home/pushpesh/miniconda3/envs/tf/lib/python3.9/site-packages/IPython/core/interactiveshell.py\", line 3318, in run_ast_nodes\n      if await self.run_code(code, result, async_=asy):\n    File \"/home/pushpesh/miniconda3/envs/tf/lib/python3.9/site-packages/IPython/core/interactiveshell.py\", line 3378, in run_code\n      exec(code_obj, self.user_global_ns, self.user_ns)\n    File \"/tmp/ipykernel_3200/1768953873.py\", line 4, in <module>\n      detections = detector.detect_faces(img)\n    File \"/home/pushpesh/miniconda3/envs/tf/lib/python3.9/site-packages/mtcnn/mtcnn.py\", line 300, in detect_faces\n      result = stage(img, result[0], result[1])\n    File \"/home/pushpesh/miniconda3/envs/tf/lib/python3.9/site-packages/mtcnn/mtcnn.py\", line 342, in __stage1\n      out = self._pnet.predict(img_y)\n    File \"/home/pushpesh/miniconda3/envs/tf/lib/python3.9/site-packages/keras/utils/traceback_utils.py\", line 65, in error_handler\n      return fn(*args, **kwargs)\n    File \"/home/pushpesh/miniconda3/envs/tf/lib/python3.9/site-packages/keras/engine/training.py\", line 2253, in predict\n      tmp_batch_outputs = self.predict_function(iterator)\n    File \"/home/pushpesh/miniconda3/envs/tf/lib/python3.9/site-packages/keras/engine/training.py\", line 2041, in predict_function\n      return step_function(self, iterator)\n    File \"/home/pushpesh/miniconda3/envs/tf/lib/python3.9/site-packages/keras/engine/training.py\", line 2027, in step_function\n      outputs = model.distribute_strategy.run(run_step, args=(data,))\n    File \"/home/pushpesh/miniconda3/envs/tf/lib/python3.9/site-packages/keras/engine/training.py\", line 2015, in run_step\n      outputs = model.predict_step(data)\n    File \"/home/pushpesh/miniconda3/envs/tf/lib/python3.9/site-packages/keras/engine/training.py\", line 1983, in predict_step\n      return self(x, training=False)\n    File \"/home/pushpesh/miniconda3/envs/tf/lib/python3.9/site-packages/keras/utils/traceback_utils.py\", line 65, in error_handler\n      return fn(*args, **kwargs)\n    File \"/home/pushpesh/miniconda3/envs/tf/lib/python3.9/site-packages/keras/engine/training.py\", line 557, in __call__\n      return super().__call__(*args, **kwargs)\n    File \"/home/pushpesh/miniconda3/envs/tf/lib/python3.9/site-packages/keras/utils/traceback_utils.py\", line 65, in error_handler\n      return fn(*args, **kwargs)\n    File \"/home/pushpesh/miniconda3/envs/tf/lib/python3.9/site-packages/keras/engine/base_layer.py\", line 1097, in __call__\n      outputs = call_fn(inputs, *args, **kwargs)\n    File \"/home/pushpesh/miniconda3/envs/tf/lib/python3.9/site-packages/keras/utils/traceback_utils.py\", line 96, in error_handler\n      return fn(*args, **kwargs)\n    File \"/home/pushpesh/miniconda3/envs/tf/lib/python3.9/site-packages/keras/engine/functional.py\", line 510, in call\n      return self._run_internal_graph(inputs, training=training, mask=mask)\n    File \"/home/pushpesh/miniconda3/envs/tf/lib/python3.9/site-packages/keras/engine/functional.py\", line 667, in _run_internal_graph\n      outputs = node.layer(*args, **kwargs)\n    File \"/home/pushpesh/miniconda3/envs/tf/lib/python3.9/site-packages/keras/utils/traceback_utils.py\", line 65, in error_handler\n      return fn(*args, **kwargs)\n    File \"/home/pushpesh/miniconda3/envs/tf/lib/python3.9/site-packages/keras/engine/base_layer.py\", line 1097, in __call__\n      outputs = call_fn(inputs, *args, **kwargs)\n    File \"/home/pushpesh/miniconda3/envs/tf/lib/python3.9/site-packages/keras/utils/traceback_utils.py\", line 96, in error_handler\n      return fn(*args, **kwargs)\n    File \"/home/pushpesh/miniconda3/envs/tf/lib/python3.9/site-packages/keras/layers/convolutional/base_conv.py\", line 283, in call\n      outputs = self.convolution_op(inputs, self.kernel)\n    File \"/home/pushpesh/miniconda3/envs/tf/lib/python3.9/site-packages/keras/layers/convolutional/base_conv.py\", line 255, in convolution_op\n      return tf.nn.convolution(\nNode: 'model_3/conv2d_12/Conv2D'\nNo algorithm worked!  Error messages:\n  Profiling failure on CUDNN engine 1#TC: UNKNOWN: CUDNN_STATUS_EXECUTION_FAILED\nin tensorflow/stream_executor/cuda/cuda_dnn.cc(4023): 'cudnnConvolutionForward( cudnn.handle(), alpha, input_nd_.handle(), input_data.opaque(), filter_.handle(), filter_data.opaque(), conv_.handle(), ToConvForwardAlgo(algo), scratch_memory.opaque(), scratch_memory.size(), beta, output_nd_.handle(), output_data.opaque())'\n  Profiling failure on CUDNN engine 1: UNKNOWN: CUDNN_STATUS_EXECUTION_FAILED\nin tensorflow/stream_executor/cuda/cuda_dnn.cc(4023): 'cudnnConvolutionForward( cudnn.handle(), alpha, input_nd_.handle(), input_data.opaque(), filter_.handle(), filter_data.opaque(), conv_.handle(), ToConvForwardAlgo(algo), scratch_memory.opaque(), scratch_memory.size(), beta, output_nd_.handle(), output_data.opaque())'\n  Profiling failure on CUDNN engine 0#TC: UNKNOWN: CUDNN_STATUS_EXECUTION_FAILED\nin tensorflow/stream_executor/cuda/cuda_dnn.cc(4023): 'cudnnConvolutionForward( cudnn.handle(), alpha, input_nd_.handle(), input_data.opaque(), filter_.handle(), filter_data.opaque(), conv_.handle(), ToConvForwardAlgo(algo), scratch_memory.opaque(), scratch_memory.size(), beta, output_nd_.handle(), output_data.opaque())'\n  Profiling failure on CUDNN engine 0: UNKNOWN: CUDNN_STATUS_EXECUTION_FAILED\nin tensorflow/stream_executor/cuda/cuda_dnn.cc(4023): 'cudnnConvolutionForward( cudnn.handle(), alpha, input_nd_.handle(), input_data.opaque(), filter_.handle(), filter_data.opaque(), conv_.handle(), ToConvForwardAlgo(algo), scratch_memory.opaque(), scratch_memory.size(), beta, output_nd_.handle(), output_data.opaque())'\n  Profiling failure on CUDNN engine 2#TC: RESOURCE_EXHAUSTED: Out of memory while trying to allocate 87330160 bytes.\n  Profiling failure on CUDNN engine 2: RESOURCE_EXHAUSTED: Out of memory while trying to allocate 87330160 bytes.\n  Profiling failure on CUDNN engine 6#TC: UNKNOWN: CUDNN_STATUS_EXECUTION_FAILED\nin tensorflow/stream_executor/cuda/cuda_dnn.cc(4023): 'cudnnConvolutionForward( cudnn.handle(), alpha, input_nd_.handle(), input_data.opaque(), filter_.handle(), filter_data.opaque(), conv_.handle(), ToConvForwardAlgo(algo), scratch_memory.opaque(), scratch_memory.size(), beta, output_nd_.handle(), output_data.opaque())'\n  Profiling failure on CUDNN engine 6: UNKNOWN: CUDNN_STATUS_EXECUTION_FAILED\nin tensorflow/stream_executor/cuda/cuda_dnn.cc(4023): 'cudnnConvolutionForward( cudnn.handle(), alpha, input_nd_.handle(), input_data.opaque(), filter_.handle(), filter_data.opaque(), conv_.handle(), ToConvForwardAlgo(algo), scratch_memory.opaque(), scratch_memory.size(), beta, output_nd_.handle(), output_data.opaque())'\n  Profiling failure on CUDNN engine 5#TC: UNKNOWN: CUDNN_STATUS_INTERNAL_ERROR\nin tensorflow/stream_executor/cuda/cuda_dnn.cc(4023): 'cudnnConvolutionForward( cudnn.handle(), alpha, input_nd_.handle(), input_data.opaque(), filter_.handle(), filter_data.opaque(), conv_.handle(), ToConvForwardAlgo(algo), scratch_memory.opaque(), scratch_memory.size(), beta, output_nd_.handle(), output_data.opaque())'\n  Profiling failure on CUDNN engine 5: UNKNOWN: CUDNN_STATUS_INTERNAL_ERROR\nin tensorflow/stream_executor/cuda/cuda_dnn.cc(4023): 'cudnnConvolutionForward( cudnn.handle(), alpha, input_nd_.handle(), input_data.opaque(), filter_.handle(), filter_data.opaque(), conv_.handle(), ToConvForwardAlgo(algo), scratch_memory.opaque(), scratch_memory.size(), beta, output_nd_.handle(), output_data.opaque())'\n  Profiling failure on CUDNN engine 7#TC: RESOURCE_EXHAUSTED: Out of memory while trying to allocate 1246011616 bytes.\n  Profiling failure on CUDNN engine 7: RESOURCE_EXHAUSTED: Out of memory while trying to allocate 1246011616 bytes.\n\t [[{{node model_3/conv2d_12/Conv2D}}]] [Op:__inference_predict_function_1831]",
     "output_type": "error",
     "traceback": [
      "\u001b[0;31m---------------------------------------------------------------------------\u001b[0m",
      "\u001b[0;31mNotFoundError\u001b[0m                             Traceback (most recent call last)",
      "Cell \u001b[0;32mIn [5], line 4\u001b[0m\n\u001b[1;32m      2\u001b[0m img \u001b[38;5;241m=\u001b[39m cv2\u001b[38;5;241m.\u001b[39mcvtColor(cv2\u001b[38;5;241m.\u001b[39mimread(image_path), cv2\u001b[38;5;241m.\u001b[39mCOLOR_BGR2RGB)\n\u001b[1;32m      3\u001b[0m detector \u001b[38;5;241m=\u001b[39m MTCNN()\n\u001b[0;32m----> 4\u001b[0m detections \u001b[38;5;241m=\u001b[39m detector\u001b[38;5;241m.\u001b[39mdetect_faces(img)\n",
      "File \u001b[0;32m~/miniconda3/envs/tf/lib/python3.9/site-packages/mtcnn/mtcnn.py:300\u001b[0m, in \u001b[0;36mMTCNN.detect_faces\u001b[0;34m(self, img)\u001b[0m\n\u001b[1;32m    298\u001b[0m \u001b[38;5;66;03m# We pipe here each of the stages\u001b[39;00m\n\u001b[1;32m    299\u001b[0m \u001b[38;5;28;01mfor\u001b[39;00m stage \u001b[38;5;129;01min\u001b[39;00m stages:\n\u001b[0;32m--> 300\u001b[0m     result \u001b[38;5;241m=\u001b[39m \u001b[43mstage\u001b[49m\u001b[43m(\u001b[49m\u001b[43mimg\u001b[49m\u001b[43m,\u001b[49m\u001b[43m \u001b[49m\u001b[43mresult\u001b[49m\u001b[43m[\u001b[49m\u001b[38;5;241;43m0\u001b[39;49m\u001b[43m]\u001b[49m\u001b[43m,\u001b[49m\u001b[43m \u001b[49m\u001b[43mresult\u001b[49m\u001b[43m[\u001b[49m\u001b[38;5;241;43m1\u001b[39;49m\u001b[43m]\u001b[49m\u001b[43m)\u001b[49m\n\u001b[1;32m    302\u001b[0m [total_boxes, points] \u001b[38;5;241m=\u001b[39m result\n\u001b[1;32m    304\u001b[0m bounding_boxes \u001b[38;5;241m=\u001b[39m []\n",
      "File \u001b[0;32m~/miniconda3/envs/tf/lib/python3.9/site-packages/mtcnn/mtcnn.py:342\u001b[0m, in \u001b[0;36mMTCNN.__stage1\u001b[0;34m(self, image, scales, stage_status)\u001b[0m\n\u001b[1;32m    339\u001b[0m img_x \u001b[38;5;241m=\u001b[39m np\u001b[38;5;241m.\u001b[39mexpand_dims(scaled_image, \u001b[38;5;241m0\u001b[39m)\n\u001b[1;32m    340\u001b[0m img_y \u001b[38;5;241m=\u001b[39m np\u001b[38;5;241m.\u001b[39mtranspose(img_x, (\u001b[38;5;241m0\u001b[39m, \u001b[38;5;241m2\u001b[39m, \u001b[38;5;241m1\u001b[39m, \u001b[38;5;241m3\u001b[39m))\n\u001b[0;32m--> 342\u001b[0m out \u001b[38;5;241m=\u001b[39m \u001b[38;5;28;43mself\u001b[39;49m\u001b[38;5;241;43m.\u001b[39;49m\u001b[43m_pnet\u001b[49m\u001b[38;5;241;43m.\u001b[39;49m\u001b[43mpredict\u001b[49m\u001b[43m(\u001b[49m\u001b[43mimg_y\u001b[49m\u001b[43m)\u001b[49m\n\u001b[1;32m    344\u001b[0m out0 \u001b[38;5;241m=\u001b[39m np\u001b[38;5;241m.\u001b[39mtranspose(out[\u001b[38;5;241m0\u001b[39m], (\u001b[38;5;241m0\u001b[39m, \u001b[38;5;241m2\u001b[39m, \u001b[38;5;241m1\u001b[39m, \u001b[38;5;241m3\u001b[39m))\n\u001b[1;32m    345\u001b[0m out1 \u001b[38;5;241m=\u001b[39m np\u001b[38;5;241m.\u001b[39mtranspose(out[\u001b[38;5;241m1\u001b[39m], (\u001b[38;5;241m0\u001b[39m, \u001b[38;5;241m2\u001b[39m, \u001b[38;5;241m1\u001b[39m, \u001b[38;5;241m3\u001b[39m))\n",
      "File \u001b[0;32m~/miniconda3/envs/tf/lib/python3.9/site-packages/keras/utils/traceback_utils.py:70\u001b[0m, in \u001b[0;36mfilter_traceback.<locals>.error_handler\u001b[0;34m(*args, **kwargs)\u001b[0m\n\u001b[1;32m     67\u001b[0m     filtered_tb \u001b[38;5;241m=\u001b[39m _process_traceback_frames(e\u001b[38;5;241m.\u001b[39m__traceback__)\n\u001b[1;32m     68\u001b[0m     \u001b[38;5;66;03m# To get the full stack trace, call:\u001b[39;00m\n\u001b[1;32m     69\u001b[0m     \u001b[38;5;66;03m# `tf.debugging.disable_traceback_filtering()`\u001b[39;00m\n\u001b[0;32m---> 70\u001b[0m     \u001b[38;5;28;01mraise\u001b[39;00m e\u001b[38;5;241m.\u001b[39mwith_traceback(filtered_tb) \u001b[38;5;28;01mfrom\u001b[39;00m \u001b[38;5;28mNone\u001b[39m\n\u001b[1;32m     71\u001b[0m \u001b[38;5;28;01mfinally\u001b[39;00m:\n\u001b[1;32m     72\u001b[0m     \u001b[38;5;28;01mdel\u001b[39;00m filtered_tb\n",
      "File \u001b[0;32m~/miniconda3/envs/tf/lib/python3.9/site-packages/tensorflow/python/eager/execute.py:54\u001b[0m, in \u001b[0;36mquick_execute\u001b[0;34m(op_name, num_outputs, inputs, attrs, ctx, name)\u001b[0m\n\u001b[1;32m     52\u001b[0m \u001b[38;5;28;01mtry\u001b[39;00m:\n\u001b[1;32m     53\u001b[0m   ctx\u001b[38;5;241m.\u001b[39mensure_initialized()\n\u001b[0;32m---> 54\u001b[0m   tensors \u001b[38;5;241m=\u001b[39m pywrap_tfe\u001b[38;5;241m.\u001b[39mTFE_Py_Execute(ctx\u001b[38;5;241m.\u001b[39m_handle, device_name, op_name,\n\u001b[1;32m     55\u001b[0m                                       inputs, attrs, num_outputs)\n\u001b[1;32m     56\u001b[0m \u001b[38;5;28;01mexcept\u001b[39;00m core\u001b[38;5;241m.\u001b[39m_NotOkStatusException \u001b[38;5;28;01mas\u001b[39;00m e:\n\u001b[1;32m     57\u001b[0m   \u001b[38;5;28;01mif\u001b[39;00m name \u001b[38;5;129;01mis\u001b[39;00m \u001b[38;5;129;01mnot\u001b[39;00m \u001b[38;5;28;01mNone\u001b[39;00m:\n",
      "\u001b[0;31mNotFoundError\u001b[0m: Graph execution error:\n\nDetected at node 'model_3/conv2d_12/Conv2D' defined at (most recent call last):\n    File \"/home/pushpesh/miniconda3/envs/tf/lib/python3.9/runpy.py\", line 197, in _run_module_as_main\n      return _run_code(code, main_globals, None,\n    File \"/home/pushpesh/miniconda3/envs/tf/lib/python3.9/runpy.py\", line 87, in _run_code\n      exec(code, run_globals)\n    File \"/home/pushpesh/miniconda3/envs/tf/lib/python3.9/site-packages/ipykernel_launcher.py\", line 17, in <module>\n      app.launch_new_instance()\n    File \"/home/pushpesh/miniconda3/envs/tf/lib/python3.9/site-packages/traitlets/config/application.py\", line 978, in launch_instance\n      app.start()\n    File \"/home/pushpesh/miniconda3/envs/tf/lib/python3.9/site-packages/ipykernel/kernelapp.py\", line 712, in start\n      self.io_loop.start()\n    File \"/home/pushpesh/miniconda3/envs/tf/lib/python3.9/site-packages/tornado/platform/asyncio.py\", line 199, in start\n      self.asyncio_loop.run_forever()\n    File \"/home/pushpesh/miniconda3/envs/tf/lib/python3.9/asyncio/base_events.py\", line 601, in run_forever\n      self._run_once()\n    File \"/home/pushpesh/miniconda3/envs/tf/lib/python3.9/asyncio/base_events.py\", line 1905, in _run_once\n      handle._run()\n    File \"/home/pushpesh/miniconda3/envs/tf/lib/python3.9/asyncio/events.py\", line 80, in _run\n      self._context.run(self._callback, *self._args)\n    File \"/home/pushpesh/miniconda3/envs/tf/lib/python3.9/site-packages/ipykernel/kernelbase.py\", line 510, in dispatch_queue\n      await self.process_one()\n    File \"/home/pushpesh/miniconda3/envs/tf/lib/python3.9/site-packages/ipykernel/kernelbase.py\", line 499, in process_one\n      await dispatch(*args)\n    File \"/home/pushpesh/miniconda3/envs/tf/lib/python3.9/site-packages/ipykernel/kernelbase.py\", line 406, in dispatch_shell\n      await result\n    File \"/home/pushpesh/miniconda3/envs/tf/lib/python3.9/site-packages/ipykernel/kernelbase.py\", line 730, in execute_request\n      reply_content = await reply_content\n    File \"/home/pushpesh/miniconda3/envs/tf/lib/python3.9/site-packages/ipykernel/ipkernel.py\", line 383, in do_execute\n      res = shell.run_cell(\n    File \"/home/pushpesh/miniconda3/envs/tf/lib/python3.9/site-packages/ipykernel/zmqshell.py\", line 528, in run_cell\n      return super().run_cell(*args, **kwargs)\n    File \"/home/pushpesh/miniconda3/envs/tf/lib/python3.9/site-packages/IPython/core/interactiveshell.py\", line 2885, in run_cell\n      result = self._run_cell(\n    File \"/home/pushpesh/miniconda3/envs/tf/lib/python3.9/site-packages/IPython/core/interactiveshell.py\", line 2940, in _run_cell\n      return runner(coro)\n    File \"/home/pushpesh/miniconda3/envs/tf/lib/python3.9/site-packages/IPython/core/async_helpers.py\", line 129, in _pseudo_sync_runner\n      coro.send(None)\n    File \"/home/pushpesh/miniconda3/envs/tf/lib/python3.9/site-packages/IPython/core/interactiveshell.py\", line 3139, in run_cell_async\n      has_raised = await self.run_ast_nodes(code_ast.body, cell_name,\n    File \"/home/pushpesh/miniconda3/envs/tf/lib/python3.9/site-packages/IPython/core/interactiveshell.py\", line 3318, in run_ast_nodes\n      if await self.run_code(code, result, async_=asy):\n    File \"/home/pushpesh/miniconda3/envs/tf/lib/python3.9/site-packages/IPython/core/interactiveshell.py\", line 3378, in run_code\n      exec(code_obj, self.user_global_ns, self.user_ns)\n    File \"/tmp/ipykernel_3200/1768953873.py\", line 4, in <module>\n      detections = detector.detect_faces(img)\n    File \"/home/pushpesh/miniconda3/envs/tf/lib/python3.9/site-packages/mtcnn/mtcnn.py\", line 300, in detect_faces\n      result = stage(img, result[0], result[1])\n    File \"/home/pushpesh/miniconda3/envs/tf/lib/python3.9/site-packages/mtcnn/mtcnn.py\", line 342, in __stage1\n      out = self._pnet.predict(img_y)\n    File \"/home/pushpesh/miniconda3/envs/tf/lib/python3.9/site-packages/keras/utils/traceback_utils.py\", line 65, in error_handler\n      return fn(*args, **kwargs)\n    File \"/home/pushpesh/miniconda3/envs/tf/lib/python3.9/site-packages/keras/engine/training.py\", line 2253, in predict\n      tmp_batch_outputs = self.predict_function(iterator)\n    File \"/home/pushpesh/miniconda3/envs/tf/lib/python3.9/site-packages/keras/engine/training.py\", line 2041, in predict_function\n      return step_function(self, iterator)\n    File \"/home/pushpesh/miniconda3/envs/tf/lib/python3.9/site-packages/keras/engine/training.py\", line 2027, in step_function\n      outputs = model.distribute_strategy.run(run_step, args=(data,))\n    File \"/home/pushpesh/miniconda3/envs/tf/lib/python3.9/site-packages/keras/engine/training.py\", line 2015, in run_step\n      outputs = model.predict_step(data)\n    File \"/home/pushpesh/miniconda3/envs/tf/lib/python3.9/site-packages/keras/engine/training.py\", line 1983, in predict_step\n      return self(x, training=False)\n    File \"/home/pushpesh/miniconda3/envs/tf/lib/python3.9/site-packages/keras/utils/traceback_utils.py\", line 65, in error_handler\n      return fn(*args, **kwargs)\n    File \"/home/pushpesh/miniconda3/envs/tf/lib/python3.9/site-packages/keras/engine/training.py\", line 557, in __call__\n      return super().__call__(*args, **kwargs)\n    File \"/home/pushpesh/miniconda3/envs/tf/lib/python3.9/site-packages/keras/utils/traceback_utils.py\", line 65, in error_handler\n      return fn(*args, **kwargs)\n    File \"/home/pushpesh/miniconda3/envs/tf/lib/python3.9/site-packages/keras/engine/base_layer.py\", line 1097, in __call__\n      outputs = call_fn(inputs, *args, **kwargs)\n    File \"/home/pushpesh/miniconda3/envs/tf/lib/python3.9/site-packages/keras/utils/traceback_utils.py\", line 96, in error_handler\n      return fn(*args, **kwargs)\n    File \"/home/pushpesh/miniconda3/envs/tf/lib/python3.9/site-packages/keras/engine/functional.py\", line 510, in call\n      return self._run_internal_graph(inputs, training=training, mask=mask)\n    File \"/home/pushpesh/miniconda3/envs/tf/lib/python3.9/site-packages/keras/engine/functional.py\", line 667, in _run_internal_graph\n      outputs = node.layer(*args, **kwargs)\n    File \"/home/pushpesh/miniconda3/envs/tf/lib/python3.9/site-packages/keras/utils/traceback_utils.py\", line 65, in error_handler\n      return fn(*args, **kwargs)\n    File \"/home/pushpesh/miniconda3/envs/tf/lib/python3.9/site-packages/keras/engine/base_layer.py\", line 1097, in __call__\n      outputs = call_fn(inputs, *args, **kwargs)\n    File \"/home/pushpesh/miniconda3/envs/tf/lib/python3.9/site-packages/keras/utils/traceback_utils.py\", line 96, in error_handler\n      return fn(*args, **kwargs)\n    File \"/home/pushpesh/miniconda3/envs/tf/lib/python3.9/site-packages/keras/layers/convolutional/base_conv.py\", line 283, in call\n      outputs = self.convolution_op(inputs, self.kernel)\n    File \"/home/pushpesh/miniconda3/envs/tf/lib/python3.9/site-packages/keras/layers/convolutional/base_conv.py\", line 255, in convolution_op\n      return tf.nn.convolution(\nNode: 'model_3/conv2d_12/Conv2D'\nNo algorithm worked!  Error messages:\n  Profiling failure on CUDNN engine 1#TC: UNKNOWN: CUDNN_STATUS_EXECUTION_FAILED\nin tensorflow/stream_executor/cuda/cuda_dnn.cc(4023): 'cudnnConvolutionForward( cudnn.handle(), alpha, input_nd_.handle(), input_data.opaque(), filter_.handle(), filter_data.opaque(), conv_.handle(), ToConvForwardAlgo(algo), scratch_memory.opaque(), scratch_memory.size(), beta, output_nd_.handle(), output_data.opaque())'\n  Profiling failure on CUDNN engine 1: UNKNOWN: CUDNN_STATUS_EXECUTION_FAILED\nin tensorflow/stream_executor/cuda/cuda_dnn.cc(4023): 'cudnnConvolutionForward( cudnn.handle(), alpha, input_nd_.handle(), input_data.opaque(), filter_.handle(), filter_data.opaque(), conv_.handle(), ToConvForwardAlgo(algo), scratch_memory.opaque(), scratch_memory.size(), beta, output_nd_.handle(), output_data.opaque())'\n  Profiling failure on CUDNN engine 0#TC: UNKNOWN: CUDNN_STATUS_EXECUTION_FAILED\nin tensorflow/stream_executor/cuda/cuda_dnn.cc(4023): 'cudnnConvolutionForward( cudnn.handle(), alpha, input_nd_.handle(), input_data.opaque(), filter_.handle(), filter_data.opaque(), conv_.handle(), ToConvForwardAlgo(algo), scratch_memory.opaque(), scratch_memory.size(), beta, output_nd_.handle(), output_data.opaque())'\n  Profiling failure on CUDNN engine 0: UNKNOWN: CUDNN_STATUS_EXECUTION_FAILED\nin tensorflow/stream_executor/cuda/cuda_dnn.cc(4023): 'cudnnConvolutionForward( cudnn.handle(), alpha, input_nd_.handle(), input_data.opaque(), filter_.handle(), filter_data.opaque(), conv_.handle(), ToConvForwardAlgo(algo), scratch_memory.opaque(), scratch_memory.size(), beta, output_nd_.handle(), output_data.opaque())'\n  Profiling failure on CUDNN engine 2#TC: RESOURCE_EXHAUSTED: Out of memory while trying to allocate 87330160 bytes.\n  Profiling failure on CUDNN engine 2: RESOURCE_EXHAUSTED: Out of memory while trying to allocate 87330160 bytes.\n  Profiling failure on CUDNN engine 6#TC: UNKNOWN: CUDNN_STATUS_EXECUTION_FAILED\nin tensorflow/stream_executor/cuda/cuda_dnn.cc(4023): 'cudnnConvolutionForward( cudnn.handle(), alpha, input_nd_.handle(), input_data.opaque(), filter_.handle(), filter_data.opaque(), conv_.handle(), ToConvForwardAlgo(algo), scratch_memory.opaque(), scratch_memory.size(), beta, output_nd_.handle(), output_data.opaque())'\n  Profiling failure on CUDNN engine 6: UNKNOWN: CUDNN_STATUS_EXECUTION_FAILED\nin tensorflow/stream_executor/cuda/cuda_dnn.cc(4023): 'cudnnConvolutionForward( cudnn.handle(), alpha, input_nd_.handle(), input_data.opaque(), filter_.handle(), filter_data.opaque(), conv_.handle(), ToConvForwardAlgo(algo), scratch_memory.opaque(), scratch_memory.size(), beta, output_nd_.handle(), output_data.opaque())'\n  Profiling failure on CUDNN engine 5#TC: UNKNOWN: CUDNN_STATUS_INTERNAL_ERROR\nin tensorflow/stream_executor/cuda/cuda_dnn.cc(4023): 'cudnnConvolutionForward( cudnn.handle(), alpha, input_nd_.handle(), input_data.opaque(), filter_.handle(), filter_data.opaque(), conv_.handle(), ToConvForwardAlgo(algo), scratch_memory.opaque(), scratch_memory.size(), beta, output_nd_.handle(), output_data.opaque())'\n  Profiling failure on CUDNN engine 5: UNKNOWN: CUDNN_STATUS_INTERNAL_ERROR\nin tensorflow/stream_executor/cuda/cuda_dnn.cc(4023): 'cudnnConvolutionForward( cudnn.handle(), alpha, input_nd_.handle(), input_data.opaque(), filter_.handle(), filter_data.opaque(), conv_.handle(), ToConvForwardAlgo(algo), scratch_memory.opaque(), scratch_memory.size(), beta, output_nd_.handle(), output_data.opaque())'\n  Profiling failure on CUDNN engine 7#TC: RESOURCE_EXHAUSTED: Out of memory while trying to allocate 1246011616 bytes.\n  Profiling failure on CUDNN engine 7: RESOURCE_EXHAUSTED: Out of memory while trying to allocate 1246011616 bytes.\n\t [[{{node model_3/conv2d_12/Conv2D}}]] [Op:__inference_predict_function_1831]"
     ]
    }
   ],
   "source": [
    "image_path = r\"/home/pushpesh/Videos/proj/img/test1.jpg\"\n",
    "img = cv2.cvtColor(cv2.imread(image_path), cv2.COLOR_BGR2RGB)\n",
    "detector = MTCNN()\n",
    "detections = detector.detect_faces(img)"
   ]
  },
  {
   "cell_type": "code",
   "execution_count": null,
   "metadata": {
    "colab": {
     "base_uri": "https://localhost:8080/",
     "height": 879
    },
    "id": "wPVKGbD3UY0l",
    "outputId": "3012454a-841c-4a96-8e38-f0f727349e0b"
   },
   "outputs": [],
   "source": [
    "import matplotlib.pyplot as plt\n",
    "\n",
    "img_with_dets = img.copy()\n",
    "min_conf = 0.9\n",
    "for det in detections:\n",
    "    if det['confidence'] >= min_conf:\n",
    "        x, y, width, height = det['box']\n",
    "        keypoints = det['keypoints']\n",
    "        cv2.rectangle(img_with_dets, (x,y), (x+width,y+height), (0,155,255), 3)\n",
    "        cv2.circle(img_with_dets, (keypoints['left_eye']), 2, (0,155,255), 2)\n",
    "        cv2.circle(img_with_dets, (keypoints['right_eye']), 2, (0,155,255), 2)\n",
    "        cv2.circle(img_with_dets, (keypoints['nose']), 2, (0,155,255), 2)\n",
    "        cv2.circle(img_with_dets, (keypoints['mouth_left']), 2, (0,155,255), 2)\n",
    "        cv2.circle(img_with_dets, (keypoints['mouth_right']), 2, (0,155,255), 2)\n",
    "plt.figure(figsize = (50,50))\n",
    "plt.imshow(img_with_dets)\n",
    "plt.axis('off')"
   ]
  },
  {
   "cell_type": "code",
   "execution_count": null,
   "metadata": {
    "id": "fRsbAlGQXFyH"
   },
   "outputs": [],
   "source": []
  }
 ],
 "metadata": {
  "colab": {
   "collapsed_sections": [],
   "provenance": []
  },
  "kernelspec": {
   "display_name": "Python 3 (ipykernel)",
   "language": "python",
   "name": "python3"
  },
  "language_info": {
   "codemirror_mode": {
    "name": "ipython",
    "version": 3
   },
   "file_extension": ".py",
   "mimetype": "text/x-python",
   "name": "python",
   "nbconvert_exporter": "python",
   "pygments_lexer": "ipython3",
   "version": "3.9.13"
  }
 },
 "nbformat": 4,
 "nbformat_minor": 4
}
